<?xml version="1.0" ?>
<sdf version="1.9">
  <model name="hamals_robot">
    <pose>0 0 0 0 0 0</pose>


    <link name="base_link">
      <pose>0.0 0.0 0.215 0.0 0.0 0.0</pose>

      <inertial>
        <mass>18.0</mass>
        <inertia>
          <ixx>0.35</ixx>
          <ixy>0.0</ixy>
          <ixz>0.0</ixz>
          <iyy>0.8</iyy>
          <iyz>0.0</iyz>
          <izz>0.95</izz>
        </inertia>
      </inertial>

      <collision name="base_link_collision">
        <geometry>
          <box>
            <size>0.7 0.45 0.35</size>
          </box>
        </geometry>
      </collision>

      <visual name="base_link_visual">
        <geometry>
          <box>
            <size>0.7 0.45 0.35</size>
          </box>
        </geometry>
        <material>
          <ambient>0.75 0.75 0.75 1.0</ambient>
          <diffuse>0.75 0.75 0.75 1.0</diffuse>
        </material>
      </visual>
    </link>



    <link name="left_drive_wheel_link">
      <pose>0.25 0.245 0.07499999999999998 1.5708 0.0 0.0</pose>

      <inertial>
        <mass>0.7</mass>
        <inertia>
          <ixx>0.002</ixx>
          <ixy>0.0</ixy>
          <ixz>0.0</ixz>
          <iyy>0.002</iyy>
          <iyz>0.0</iyz>
          <izz>0.001</izz>
        </inertia>
      </inertial>

      <collision name="left_drive_wheel_link_collision">
        <geometry>
          <cylinder>
            <radius>0.075</radius>
            <length>0.04</length>
          </cylinder>
        </geometry>
      </collision>

      <visual name="left_drive_wheel_link_visual">
        <geometry>
          <cylinder>
            <radius>0.075</radius>
            <length>0.04</length>
          </cylinder>
        </geometry>
        <material>
          <ambient>0.02 0.02 0.02 1.0</ambient>
          <diffuse>0.02 0.02 0.02 1.0</diffuse>
        </material>
      </visual>
    </link>


    <joint name="left_drive_wheel_joint" type="revolute">
      <parent>base_link</parent>
      <child>left_drive_wheel_link</child>
      <axis>
        <xyz>0.0 0.0 1.0</xyz>
        <limit>
          <lower>-1e16</lower>
          <upper>1e16</upper>
        </limit>
      </axis>
    </joint>



    <link name="right_drive_wheel_link">
      <pose>0.25 -0.245 0.07499999999999998 1.5708 0.0 0.0</pose>

      <inertial>
        <mass>0.7</mass>
        <inertia>
          <ixx>0.002</ixx>
          <ixy>0.0</ixy>
          <ixz>0.0</ixz>
          <iyy>0.002</iyy>
          <iyz>0.0</iyz>
          <izz>0.001</izz>
        </inertia>
      </inertial>

      <collision name="right_drive_wheel_link_collision">
        <geometry>
          <cylinder>
            <radius>0.075</radius>
            <length>0.04</length>
          </cylinder>
        </geometry>
      </collision>

      <visual name="right_drive_wheel_link_visual">
        <geometry>
          <cylinder>
            <radius>0.075</radius>
            <length>0.04</length>
          </cylinder>
        </geometry>
        <material>
          <ambient>0.02 0.02 0.02 1.0</ambient>
          <diffuse>0.02 0.02 0.02 1.0</diffuse>
        </material>
      </visual>
    </link>


    <joint name="right_drive_wheel_joint" type="revolute">
      <parent>base_link</parent>
      <child>right_drive_wheel_link</child>
      <axis>
        <xyz>0.0 0.0 1.0</xyz>
        <limit>
          <lower>-1e16</lower>
          <upper>1e16</upper>
        </limit>
      </axis>
    </joint>



    <link name="rear_center_caster_link">
      <pose>-0.26 0.0 0.04000000000000001 0.0 0.0 0.0</pose>

      <inertial>
        <mass>0.3</mass>
        <inertia>
          <ixx>0.001</ixx>
          <ixy>0.0</ixy>
          <ixz>0.0</ixz>
          <iyy>0.001</iyy>
          <iyz>0.0</iyz>
          <izz>0.001</izz>
        </inertia>
      </inertial>

      <collision name="rear_center_caster_link_collision">
        <geometry>
          <sphere>
            <radius>0.04</radius>
          </sphere>
        </geometry>
      </collision>

      <visual name="rear_center_caster_link_visual">
        <geometry>
          <sphere>
            <radius>0.04</radius>
          </sphere>
        </geometry>
        <material>
          <ambient>0.02 0.02 0.02 1.0</ambient>
          <diffuse>0.02 0.02 0.02 1.0</diffuse>
        </material>
      </visual>
    </link>


    <joint name="rear_center_caster_joint" type="fixed">
      <parent>base_link</parent>
      <child>rear_center_caster_link</child>
    </joint>


    <link name="forklift_mast_link">
      <pose>0.35 0.0 0.215 0.0 0.0 0.0</pose>

      <inertial>
        <mass>2.0</mass>
        <inertia>
          <ixx>0.05</ixx>
          <ixy>0.0</ixy>
          <ixz>0.0</ixz>
          <iyy>0.05</iyy>
          <iyz>0.0</iyz>
          <izz>0.02</izz>
        </inertia>
      </inertial>

      <collision name="forklift_mast_collision">
        <geometry>
          <box>
            <size>0.05 0.36 0.35</size>
          </box>
        </geometry>
      </collision>

      <visual name="left_mast_column_visual">
        <pose>0.0 0.14 0.0 0.0 0.0 0.0</pose>
        <geometry>
          <box>
            <size>0.05 0.06 0.35</size>
          </box>
        </geometry>
        <material>
          <ambient>0.25 0.25 0.25 1.0</ambient>
          <diffuse>0.25 0.25 0.25 1.0</diffuse>
        </material>
      </visual>

      <visual name="right_mast_column_visual">
        <pose>0.0 -0.14 0.0 0.0 0.0 0.0</pose>
        <geometry>
          <box>
            <size>0.05 0.06 0.35</size>
          </box>
        </geometry>
        <material>
          <ambient>0.25 0.25 0.25 1.0</ambient>
          <diffuse>0.25 0.25 0.25 1.0</diffuse>
        </material>
      </visual>
    </link>

    <joint name="forklift_mast_joint" type="fixed">
      <parent>base_link</parent>
      <child>forklift_mast_link</child>
    </joint>



    <link name="fork_carriage_link">
      <pose>0.38 0.0 0.14 0.0 0.0 0.0</pose>

      <inertial>
        <mass>1.5</mass>
        <inertia>
          <ixx>0.02</ixx>
          <ixy>0.0</ixy>
          <ixz>0.0</ixz>
          <iyy>0.03</iyy>
          <iyz>0.0</iyz>
          <izz>0.04</izz>
        </inertia>
      </inertial>

      <collision name="fork_carriage_link_collision">
        <geometry>
          <box>
            <size>0.04 0.36 0.12</size>
          </box>
        </geometry>
      </collision>

      <visual name="fork_carriage_link_visual">
        <geometry>
          <box>
            <size>0.04 0.36 0.12</size>
          </box>
        </geometry>
        <material>
          <ambient>0.35 0.35 0.35 1.0</ambient>
          <diffuse>0.35 0.35 0.35 1.0</diffuse>
        </material>
      </visual>
    </link>


    <joint name="forklift_lift_joint" type="prismatic">
      <parent>forklift_mast_link</parent>
      <child>fork_carriage_link</child>
      <axis>
        <xyz>0.0 0.0 1.0</xyz>
        <limit>
          <lower>0.0</lower>
          <upper>0.2</upper>
          <effort>100.0</effort>
          <velocity>0.15</velocity>
        </limit>
      </axis>
    </joint>



    <link name="left_fork_link">
      <pose>0.605 0.14 0.06000000000000001 0.0 0.0 0.0</pose>

      <inertial>
        <mass>0.8</mass>
        <inertia>
          <ixx>0.01</ixx>
          <ixy>0.0</ixy>
          <ixz>0.0</ixz>
          <iyy>0.03</iyy>
          <iyz>0.0</iyz>
          <izz>0.03</izz>
        </inertia>
      </inertial>

      <collision name="left_fork_link_collision">
        <geometry>
          <box>
            <size>0.45 0.06 0.04</size>
          </box>
        </geometry>
      </collision>

      <visual name="left_fork_link_visual">
        <geometry>
          <box>
            <size>0.45 0.06 0.04</size>
          </box>
        </geometry>
        <material>
          <ambient>0.3 0.3 0.3 1.0</ambient>
          <diffuse>0.3 0.3 0.3 1.0</diffuse>
        </material>
      </visual>
    </link>


    <joint name="left_fork_joint" type="fixed">
      <parent>fork_carriage_link</parent>
      <child>left_fork_link</child>
    </joint>



    <link name="right_fork_link">
      <pose>0.605 -0.14 0.06000000000000001 0.0 0.0 0.0</pose>

      <inertial>
        <mass>0.8</mass>
        <inertia>
          <ixx>0.01</ixx>
          <ixy>0.0</ixy>
          <ixz>0.0</ixz>
          <iyy>0.03</iyy>
          <iyz>0.0</iyz>
          <izz>0.03</izz>
        </inertia>
      </inertial>

      <collision name="right_fork_link_collision">
        <geometry>
          <box>
            <size>0.45 0.06 0.04</size>
          </box>
        </geometry>
      </collision>

      <visual name="right_fork_link_visual">
        <geometry>
          <box>
            <size>0.45 0.06 0.04</size>
          </box>
        </geometry>
        <material>
          <ambient>0.3 0.3 0.3 1.0</ambient>
          <diffuse>0.3 0.3 0.3 1.0</diffuse>
        </material>
      </visual>
    </link>


    <joint name="right_fork_joint" type="fixed">
      <parent>fork_carriage_link</parent>
      <child>right_fork_link</child>
    </joint>



    <link name="lidar_mount_link">
      <pose>0.0 0.0 0.41000000000000003 0.0 0.0 0.0</pose>

      <inertial>
        <mass>0.2</mass>
        <inertia>
          <ixx>0.0005</ixx>
          <ixy>0.0</ixy>
          <ixz>0.0</ixz>
          <iyy>0.0005</iyy>
          <iyz>0.0</iyz>
          <izz>0.0005</izz>
        </inertia>
      </inertial>

      <collision name="lidar_mount_link_collision">
        <geometry>
          <cylinder>
            <radius>0.06</radius>
            <length>0.04</length>
          </cylinder>
        </geometry>
      </collision>

      <visual name="lidar_mount_link_visual">
        <geometry>
          <cylinder>
            <radius>0.06</radius>
            <length>0.04</length>
          </cylinder>
        </geometry>
        <material>
          <ambient>0.2 0.2 0.2 1.0</ambient>
          <diffuse>0.2 0.2 0.2 1.0</diffuse>
        </material>
      </visual>
    </link>


    <joint name="lidar_mount_joint" type="fixed">
      <parent>base_link</parent>
      <child>lidar_mount_link</child>
    </joint>



    <link name="lidar_link">
      <pose>0.0 0.0 0.45 0.0 0.0 0.0</pose>

      <inertial>
        <mass>0.25</mass>
        <inertia>
          <ixx>0.0008</ixx>
          <ixy>0.0</ixy>
          <ixz>0.0</ixz>
          <iyy>0.0008</iyy>
          <iyz>0.0</iyz>
          <izz>0.0008</izz>
        </inertia>
      </inertial>

      <collision name="lidar_link_collision">
        <geometry>
          <cylinder>
            <radius>0.045</radius>
            <length>0.04</length>
          </cylinder>
        </geometry>
      </collision>

      <visual name="lidar_link_visual">
        <geometry>
          <cylinder>
            <radius>0.045</radius>
            <length>0.04</length>
          </cylinder>
        </geometry>
        <material>
          <ambient>0.0 0.2 0.8 1.0</ambient>
          <diffuse>0.0 0.2 0.8 1.0</diffuse>
        </material>
      </visual>
    </link>


    <joint name="lidar_joint" type="fixed">
      <parent>lidar_mount_link</parent>
      <child>lidar_link</child>
    </joint>


  </model>
</sdf>
